# Error Cause

🎉 Error cause 是第一个由中国公司（阿里巴巴 TC39 代表 legendecas）代表主导推动的 JavaScript 达到 stage 4 的新特性提案！

这个提案简单理解就是：对 Error 的来源进行一次再包装；

例子：

```js
async function getSolution() {
  const rawResource = await fetch('//domain/resource-a')
    .catch(err => {
      // 平时我们要抛出错误有以下几种方式：
      // 1. throw new Error('Download raw resource failed: ' + err.message);
      // 2. const wrapErr = new Error('Download raw resource failed');
      //    wrapErr.cause = err;
      //    throw wrapErr;
      // 3. class CustomError extends Error {
      //      constructor(msg, cause) {
      //        super(msg);
      //        this.cause = cause;
      //      }
      //    }
      //    throw new CustomError('Download raw resource failed', err);
    })
  const jobResult = doComputationalHeavyJob(rawResource);
  await fetch('//domain/upload', { method: 'POST', body: jobResult });
}

await doJob(); // => TypeError: Failed to fetch
```

在新的提案中，加入了 cause 来收集原因，规范化整个错误抛出和收集：

Error Constructor 新增了一个可选的参数 options，其中可以设置 cause 并且接受任意 JavaScript 值，把这个值赋值到新创建的 error.cause 上。

```js
async function doJob() {
  const rawResource = await fetch('//domain/resource-a')
    .catch(err => {
      // 抛出一个低等级错误err，可以通过 cause 包装成高等级错误 Error
      throw new Error('Download raw resource failed', { cause: err });
    });
  const jobResult = doComputationalHeavyJob(rawResource);
  await fetch('//domain/upload', { method: 'POST', body: jobResult })
    .catch(err => {
      throw new Error('Upload job result failed', { cause: err });
    });
}

try {
  await doJob();
} catch (e) {
  console.log(e);
  console.log('Caused by', e.cause);
}
// Error: Upload job result failed
// Caused by TypeError: Failed to fetch
```

有了这个后，各种插件库的形形色色的错误类可以简单点了。
